Traceback (most recent call last):
  File "C:\Users\hiren\OneDrive\Desktop\work with smita\PointCloudNet\main.py", line 95, in <module>
    model = PointCloudFeatLearning(args.raw_dir, args.kernel_type, args.threshold, args.device).to(args.device)
  File "C:\Users\hiren\OneDrive\Desktop\work with smita\PointCloudNet\models\graph_learning.py", line 122, in __init__
    self.input_dim = self.graph_feat(torch.tensor(self.subsampled_pcs[0], dtype=torch.float).to(device)).shape[1]
  File "C:\Users\hiren\anaconda3\envs\pcenv\lib\site-packages\torch\nn\modules\module.py", line 1553, in _wrapped_call_impl
    return self._call_impl(*args, **kwargs)
  File "C:\Users\hiren\anaconda3\envs\pcenv\lib\site-packages\torch\nn\modules\module.py", line 1562, in _call_impl
    return forward_call(*args, **kwargs)
  File "C:\Users\hiren\OneDrive\Desktop\work with smita\PointCloudNet\models\graph_learning.py", line 103, in forward
    psi = gwt.generate_timepoint_feature()
  File "C:\Users\hiren\OneDrive\Desktop\work with smita\PointCloudNet\models\GWT.py", line 46, in generate_timepoint_feature
    F2 = self.second_order_feature(u)
  File "C:\Users\hiren\OneDrive\Desktop\work with smita\PointCloudNet\models\GWT.py", line 38, in second_order_feature
    u1 = torch.cat((u1, torch.abs(self.psi[j_prime]@u[j])), 1)
IndexError: list index out of range